Workbook

Sheet Summary
A1: Dataiku DSS Diagnosis - Checklist Review Summary
A3: Bundle | B3: dku_diagnosis_2026-07-22-08-21-05 (Users/boonleeeu/.../Configs/)
A4: Diagnosis taken | B4: 2026-07-22 08:21 UTC
A5: Node | B5: Design node p4d, installid GbpIpatzv3MFrFfE6MwSlXCg, host gcp9234prdapp04 (GCP VM)
A6: DSS version | B6: 14.4.3 (latest GA: 15.0.2, 24 Sep 2026)
A7: Host | B7: RHEL 8.10, 8 vCPU (AMD EPYC 7B13), ~62GB RAM, no swap; DATA_DIR on 800GB LVM (74% used)
A8: Compute | B8: Spark + containerized execution on manual K8s cluster "P4D" (GKE); 25 users; SSO via Azure AD OIDC
A9: Generated | B9: 2026-09-25
A10: Reviewer | B10: Claude (AI-assisted review) - bundle dku_diagnosis_2026-07-22-08-21-05 (node p4d, DSS 14.4.3)
A12: Overall status counts
A13: Status | B13: All items | C13: Must-have | D13: Nice-to-have
A14: Pass | B14: =COUNTIF('Architecture, Compute & Infrast'!V:V,$A14)+COUNTIF('Enterprise-grade Security, Perm'!V:V,$A14)+COUNTIF('Generative AI Acceleration & In'!V:V,$A14)+COUNTIF('Scalable Performance, Stability'!V:V,$A14)+COUNTIF('Advanced Security Options (DSS '!V:V,$A14) -> 15 | C14: =COUNTIFS('Architecture, Compute & Infrast'!V:V,$A14,'Architecture, Compute & Infrast'!B:B,"must_have")+COUNTIFS('Enterprise-grade Security, Perm'!V:V,$A14,'Enterprise-grade Security, Perm'!B:B,"must_have")+COUNTIFS('Generative AI Acceleration & In'!V:V,$A14,'Generative AI Acceleration & In'!B:B,"must_have")+COUNTIFS('Scalable Performance, Stability'!V:V,$A14,'Scalable Performance, Stability'!B:B,"must_have")+COUNTIFS('Advanced Security Options (DSS '!V:V,$A14,'Advanced Security Options (DSS '!B:B,"must_have") -> 9 | D14: =COUNTIFS('Architecture, Compute & Infrast'!V:V,$A14,'Architecture, Compute & Infrast'!B:B,"nice_to_have")+COUNTIFS('Enterprise-grade Security, Perm'!V:V,$A14,'Enterprise-grade Security, Perm'!B:B,"nice_to_have")+COUNTIFS('Generative AI Acceleration & In'!V:V,$A14,'Generative AI Acceleration & In'!B:B,"nice_to_have")+COUNTIFS('Scalable Performance, Stability'!V:V,$A14,'Scalable Performance, Stability'!B:B,"nice_to_have")+COUNTIFS('Advanced Security Options (DSS '!V:V,$A14,'Advanced Security Options (DSS '!B:B,"nice_to_have") -> 6
A15: Fail | B15: =COUNTIF('Architecture, Compute & Infrast'!V:V,$A15)+COUNTIF('Enterprise-grade Security, Perm'!V:V,$A15)+COUNTIF('Generative AI Acceleration & In'!V:V,$A15)+COUNTIF('Scalable Performance, Stability'!V:V,$A15)+COUNTIF('Advanced Security Options (DSS '!V:V,$A15) -> 21 | C15: =COUNTIFS('Architecture, Compute & Infrast'!V:V,$A15,'Architecture, Compute & Infrast'!B:B,"must_have")+COUNTIFS('Enterprise-grade Security, Perm'!V:V,$A15,'Enterprise-grade Security, Perm'!B:B,"must_have")+COUNTIFS('Generative AI Acceleration & In'!V:V,$A15,'Generative AI Acceleration & In'!B:B,"must_have")+COUNTIFS('Scalable Performance, Stability'!V:V,$A15,'Scalable Performance, Stability'!B:B,"must_have")+COUNTIFS('Advanced Security Options (DSS '!V:V,$A15,'Advanced Security Options (DSS '!B:B,"must_have") -> 14 | D15: =COUNTIFS('Architecture, Compute & Infrast'!V:V,$A15,'Architecture, Compute & Infrast'!B:B,"nice_to_have")+COUNTIFS('Enterprise-grade Security, Perm'!V:V,$A15,'Enterprise-grade Security, Perm'!B:B,"nice_to_have")+COUNTIFS('Generative AI Acceleration & In'!V:V,$A15,'Generative AI Acceleration & In'!B:B,"nice_to_have")+COUNTIFS('Scalable Performance, Stability'!V:V,$A15,'Scalable Performance, Stability'!B:B,"nice_to_have")+COUNTIFS('Advanced Security Options (DSS '!V:V,$A15,'Advanced Security Options (DSS '!B:B,"nice_to_have") -> 7
A16: Partial | B16: =COUNTIF('Architecture, Compute & Infrast'!V:V,$A16)+COUNTIF('Enterprise-grade Security, Perm'!V:V,$A16)+COUNTIF('Generative AI Acceleration & In'!V:V,$A16)+COUNTIF('Scalable Performance, Stability'!V:V,$A16)+COUNTIF('Advanced Security Options (DSS '!V:V,$A16) -> 8 | C16: =COUNTIFS('Architecture, Compute & Infrast'!V:V,$A16,'Architecture, Compute & Infrast'!B:B,"must_have")+COUNTIFS('Enterprise-grade Security, Perm'!V:V,$A16,'Enterprise-grade Security, Perm'!B:B,"must_have")+COUNTIFS('Generative AI Acceleration & In'!V:V,$A16,'Generative AI Acceleration & In'!B:B,"must_have")+COUNTIFS('Scalable Performance, Stability'!V:V,$A16,'Scalable Performance, Stability'!B:B,"must_have")+COUNTIFS('Advanced Security Options (DSS '!V:V,$A16,'Advanced Security Options (DSS '!B:B,"must_have") -> 3 | D16: =COUNTIFS('Architecture, Compute & Infrast'!V:V,$A16,'Architecture, Compute & Infrast'!B:B,"nice_to_have")+COUNTIFS('Enterprise-grade Security, Perm'!V:V,$A16,'Enterprise-grade Security, Perm'!B:B,"nice_to_have")+COUNTIFS('Generative AI Acceleration & In'!V:V,$A16,'Generative AI Acceleration & In'!B:B,"nice_to_have")+COUNTIFS('Scalable Performance, Stability'!V:V,$A16,'Scalable Performance, Stability'!B:B,"nice_to_have")+COUNTIFS('Advanced Security Options (DSS '!V:V,$A16,'Advanced Security Options (DSS '!B:B,"nice_to_have") -> 5
A17: Needs Review | B17: =COUNTIF('Architecture, Compute & Infrast'!V:V,$A17)+COUNTIF('Enterprise-grade Security, Perm'!V:V,$A17)+COUNTIF('Generative AI Acceleration & In'!V:V,$A17)+COUNTIF('Scalable Performance, Stability'!V:V,$A17)+COUNTIF('Advanced Security Options (DSS '!V:V,$A17) -> 12 | C17: =COUNTIFS('Architecture, Compute & Infrast'!V:V,$A17,'Architecture, Compute & Infrast'!B:B,"must_have")+COUNTIFS('Enterprise-grade Security, Perm'!V:V,$A17,'Enterprise-grade Security, Perm'!B:B,"must_have")+COUNTIFS('Generative AI Acceleration & In'!V:V,$A17,'Generative AI Acceleration & In'!B:B,"must_have")+COUNTIFS('Scalable Performance, Stability'!V:V,$A17,'Scalable Performance, Stability'!B:B,"must_have")+COUNTIFS('Advanced Security Options (DSS '!V:V,$A17,'Advanced Security Options (DSS '!B:B,"must_have") -> 6 | D17: =COUNTIFS('Architecture, Compute & Infrast'!V:V,$A17,'Architecture, Compute & Infrast'!B:B,"nice_to_have")+COUNTIFS('Enterprise-grade Security, Perm'!V:V,$A17,'Enterprise-grade Security, Perm'!B:B,"nice_to_have")+COUNTIFS('Generative AI Acceleration & In'!V:V,$A17,'Generative AI Acceleration & In'!B:B,"nice_to_have")+COUNTIFS('Scalable Performance, Stability'!V:V,$A17,'Scalable Performance, Stability'!B:B,"nice_to_have")+COUNTIFS('Advanced Security Options (DSS '!V:V,$A17,'Advanced Security Options (DSS '!B:B,"nice_to_have") -> 6
A18: Not Applicable | B18: =COUNTIF('Architecture, Compute & Infrast'!V:V,$A18)+COUNTIF('Enterprise-grade Security, Perm'!V:V,$A18)+COUNTIF('Generative AI Acceleration & In'!V:V,$A18)+COUNTIF('Scalable Performance, Stability'!V:V,$A18)+COUNTIF('Advanced Security Options (DSS '!V:V,$A18) -> 11 | C18: =COUNTIFS('Architecture, Compute & Infrast'!V:V,$A18,'Architecture, Compute & Infrast'!B:B,"must_have")+COUNTIFS('Enterprise-grade Security, Perm'!V:V,$A18,'Enterprise-grade Security, Perm'!B:B,"must_have")+COUNTIFS('Generative AI Acceleration & In'!V:V,$A18,'Generative AI Acceleration & In'!B:B,"must_have")+COUNTIFS('Scalable Performance, Stability'!V:V,$A18,'Scalable Performance, Stability'!B:B,"must_have")+COUNTIFS('Advanced Security Options (DSS '!V:V,$A18,'Advanced Security Options (DSS '!B:B,"must_have") -> 6 | D18: =COUNTIFS('Architecture, Compute & Infrast'!V:V,$A18,'Architecture, Compute & Infrast'!B:B,"nice_to_have")+COUNTIFS('Enterprise-grade Security, Perm'!V:V,$A18,'Enterprise-grade Security, Perm'!B:B,"nice_to_have")+COUNTIFS('Generative AI Acceleration & In'!V:V,$A18,'Generative AI Acceleration & In'!B:B,"nice_to_have")+COUNTIFS('Scalable Performance, Stability'!V:V,$A18,'Scalable Performance, Stability'!B:B,"nice_to_have")+COUNTIFS('Advanced Security Options (DSS '!V:V,$A18,'Advanced Security Options (DSS '!B:B,"nice_to_have") -> 5
A19: Total | B19: =SUM(B14:B18) -> 67 | C19: =SUM(C14:C18) -> 38 | D19: =SUM(D14:D18) -> 29
A21: Per-section breakdown
A22: Section | B22: Pass | C22: Fail | D22: Partial | E22: Needs Review | F22: Not Applicable | G22: Total
A23: Architecture, Compute & Infrast | B23: =COUNTIF('Architecture, Compute & Infrast'!V:V,"Pass") -> 5 | C23: =COUNTIF('Architecture, Compute & Infrast'!V:V,"Fail") -> 2 | D23: =COUNTIF('Architecture, Compute & Infrast'!V:V,"Partial") -> 5 | E23: =COUNTIF('Architecture, Compute & Infrast'!V:V,"Needs Review") -> 5 | F23: =COUNTIF('Architecture, Compute & Infrast'!V:V,"Not Applicable") -> 0 | G23: =SUM(B23:F23) -> 17
A24: Enterprise-grade Security, Perm | B24: =COUNTIF('Enterprise-grade Security, Perm'!V:V,"Pass") -> 4 | C24: =COUNTIF('Enterprise-grade Security, Perm'!V:V,"Fail") -> 0 | D24: =COUNTIF('Enterprise-grade Security, Perm'!V:V,"Partial") -> 2 | E24: =COUNTIF('Enterprise-grade Security, Perm'!V:V,"Needs Review") -> 3 | F24: =COUNTIF('Enterprise-grade Security, Perm'!V:V,"Not Applicable") -> 1 | G24: =SUM(B24:F24) -> 10
A25: Generative AI Acceleration & In | B25: =COUNTIF('Generative AI Acceleration & In'!V:V,"Pass") -> 1 | C25: =COUNTIF('Generative AI Acceleration & In'!V:V,"Fail") -> 1 | D25: =COUNTIF('Generative AI Acceleration & In'!V:V,"Partial") -> 0 | E25: =COUNTIF('Generative AI Acceleration & In'!V:V,"Needs Review") -> 1 | F25: =COUNTIF('Generative AI Acceleration & In'!V:V,"Not Applicable") -> 8 | G25: =SUM(B25:F25) -> 11
A26: Scalable Performance, Stability | B26: =COUNTIF('Scalable Performance, Stability'!V:V,"Pass") -> 2 | C26: =COUNTIF('Scalable Performance, Stability'!V:V,"Fail") -> 8 | D26: =COUNTIF('Scalable Performance, Stability'!V:V,"Partial") -> 1 | E26: =COUNTIF('Scalable Performance, Stability'!V:V,"Needs Review") -> 3 | F26: =COUNTIF('Scalable Performance, Stability'!V:V,"Not Applicable") -> 2 | G26: =SUM(B26:F26) -> 16
A27: Advanced Security Options (DSS | B27: =COUNTIF('Advanced Security Options (DSS '!V:V,"Pass") -> 3 | C27: =COUNTIF('Advanced Security Options (DSS '!V:V,"Fail") -> 10 | D27: =COUNTIF('Advanced Security Options (DSS '!V:V,"Partial") -> 0 | E27: =COUNTIF('Advanced Security Options (DSS '!V:V,"Needs Review") -> 0 | F27: =COUNTIF('Advanced Security Options (DSS '!V:V,"Not Applicable") -> 0 | G27: =SUM(B27:F27) -> 13
A29: Critical findings - must-have items that Fail (root cause first)
A30: ID | B30: Section | C30: Title | D30: Status | E30: Key point
A31: SCALE-009 | B31: Scalable Performance, Stability | C31: Flow Limits Sizing (Max Jobs, Max Activities) | D31: Fail | E31: CRITICAL, and the likely root cause of the instability. Max running jobs = 0 means no limit. Each job spawns a 2GB-heap JEK that is not in any cgroup, so concurrent jobs can push the 62GB, no-swap host past physical RAM, on top of the 40G cgroup budget and the 8g backend. That matches the native-memory crash dumps (Mar and Jul 2026). Fix: set maxRunningJobs using the 5-step framework, e.g. 62GB - OS ~4GB - backend 8g ~ 50GB; about 70% to cgroups (~35-40G) leaves ~10-12GB for JEKs, so about 5 concurrent jobs at 2g. Raise maxRunningActivities to 30-50 only as a backstop above Max Jobs; the current value of 5 is well below the recommended band. Also offload recipes to K8s (ARCH-016) to cut host memory pressure. Linked: SEC-004, SCALE-008.
A32: SCALE-001 | B32: Scalable Performance, Stability | C32: External PostgreSQL Runtime Database | D32: Fail | E32: The runtime DB is still the embedded H2, which is not production-grade for a 25-user instance. Migrate to an external PostgreSQL. Set maxPooledExternalConnections to at least 2x Postgres max_connections, and align DB backups with DSS backups (SCALE-005).
A33: ARCH-004 | B33: Architecture, Compute & Infrast | C33: SSD Storage for DSS | D33: Fail | E33: DSS's own sanity check flags rotational storage for DATA_DIR. Caveat: this is a GCP VM (hostname gcp9234prdapp04, metadata.google.internal), and GCP persistent disks always report ROTA=1. Confirm the actual PD type (pd-standard is HDD; pd-balanced/pd-ssd are SSD). If it is pd-standard, migrate /apps to pd-balanced or pd-ssd. With 25 users and heavy logs, disk I/O matters.
A34: SCALE-007 | B34: Scalable Performance, Stability | C34: Backend.log Error Review | D34: Fail | E34: Several systemic, recurring errors: (1) unified-monitoring graphite parsing and RRD writes for API deployments on an old 'PND_Local' infra (stale deployments or monitoring entries; clean up or fix); (2) scenarios whose run-as users (ds10, vgupta11) no longer exist (reassign or disable; see SCALE-004); (3) orphaned code-studio webapp executions calling back (clean up stale K8s code-studio deployments; see ARCH-012). None crashes DSS on its own, but together they flood the logs and hide real problems.
A35: SCALE-004 | B35: Scalable Performance, Stability | C35: Admin Project for Garbage Collection | D35: Fail | E35: An admin project exists but has no garbage-collection scenarios, and its one scheduled scenario is broken (its run-as user was deleted). Add scheduled macros for old job logs/scenario runs, idle Jupyter kernels and temp files per the Setup Maintenance Jobs wiki, and fix the run-as user. Log volume is high: backend/nginx/ipython logs rotate at 100MB.
A36: SCALE-012 | B36: Scalable Performance, Stability | C36: Cloud Object Storage Configuration (Details Readable By, HDFS Interface) | D36: Fail | E36: Spark is enabled and used, but one Azure connection has no details-readable groups (DSS itself warns), and none of the three cloud storage connections has an HDFS interface. Set GS for GCS, and ABFS (if hierarchical namespace is enabled) or WASB for Azure. Grant details-read to the groups that run Spark on these connections.
A37: SCALE-015 | B37: Scalable Performance, Stability | C37: Amazon Redshift, Google BigQuery, Azure Synapse Connection Configuration | D37: Fail | E37: Automatic fast-write is off on both BigQuery connections, so writes go row-by-row through DSS. Enable it, pointing to a GCS connection with compatible auth (the ear21183 GCS connection is a natural pairing for ear21183 BigQuery). No Redshift or Synapse connections exist.
A38: SCALE-011 | B38: Scalable Performance, Stability | C38: Remove filesystem_root Connection | D38: Fail | E38: filesystem_root still exists. Access is limited to admin and data-scientist groups, which reduces the risk but still exposes the whole server filesystem. Check usage in Admin > Monitoring. If used, create a scoped connection to the specific path, migrate, then delete filesystem_root.
A39: ADVSEC-001 | B39: Advanced Security Options (DSS | C39: Hiding error stacks | D39: Fail | E39: Stack traces are shown to logged-in users. Set security.hideErrorStacks=true.
A40: ADVSEC-004 | B40: Advanced Security Options (DSS | C40: Expiring sessions | D40: Fail | E40: Sessions never expire. Set a finite idle timeout and/or maximum duration (e.g. 8-12h max, 60-120 min idle), and warn users about possible loss of unsaved work in Jupyter.
A41: ADVSEC-005 | B41: Advanced Security Options (DSS | C41: Forcing a single session per user | D41: Fail | E41: Multiple concurrent sessions per user are allowed (the default). Enable 'Force single session per user' if it fits how users work.
... A44: GENAI-003 | B44: Generative AI Acceleration & In | C44: Trace Explorer Default Configuration | D44: Fail | E44: The Trace Explorer plugin is installed and LLM Mesh is in heavy use (9 AzureOpenAI connections, cost quotas), but no default project/webapp is set, so 'View traces' shortcuts will not work. Create a Trace Explorer webapp and set it in Admin > Settings > LLM Mesh > Trace.
A46: Other must-have items - Partial or Needs Review
A47: ID | B47: Section | C47: Title | D47: Status | E47: Key point
...

Sheet Architecture, Compute & Infrast
A1: id | B1: priority | C1: check_type | D1: subtopic | E1: title | F1: statement | G1: parameter_hint | H1: operator | I1: expected_value | J1: unit | K1: expected_condition_notes | L1: supporting_evidence | M1: contradicting_evidence | N1: insufficient_evidence_handling | O1: rationale | P1: dataiku_concepts | Q1: source_document | R1: source_page | S1: source_section | T1: confidence | U1: ambiguity_notes | V1: validation_status | W1: evidence_found | X1: notes | Y1: validated_at | Z1: validated_by
A2: ARCH-001 | B2: must_have | C2: qualitative_practice | D2: Deployment Infrastructure | E2: Separation of Design and Automation Nodes | F2: Production-grade Dataiku deployments should separate experimental/design work from production runs by leveraging dedicated automation nodes; reviewers should discuss the Design -> Deployer -> Automation Node architecture with the customer and flag gaps, even though standing up new nodes is out of scope for the review itself. | L2: Diagnosis shows a distinct automation node (or nodes) separate from the design node, with a deployer configured and bundles being pushed from design to automation. | M2: Only a single design node is used to run both experimentation and production workloads, with no automation node or deployer in use. | N2: If the diagnosis file does not expose node topology/roles, flag needs_manual_review and recommend discussing the Design -> Deployer -> Automation architecture directly with the customer. | O2: Mixing experimental and production work on the same node risks instability and is not considered production-ready. | P2: Design node, Automation node, Deployer, Bundles | Q2: architecture_compute_cost | R2: 1, 2 | S2: Dataiku Deployment Infrastructure | MUST HAVE; Dataiku Deployment Infrastructure | MUST HAVE | T2: high | V2: Partial | W2: apps/dss/data_design/install.ini: nodetype=design, nodeid=p4d. apps/dss/data_design/config/general-settings.json deployerClientSettings.mode=LOCAL (a remote nodeUrl https://deploy.ds.p.data.slb.com/ is recorded but not in use); config/project-deployer has only projects/ADMINISTRATIONPROJECT.json and no infrastructures; config/api-deployer/infras/P4D_Local.json type=STATIC, stage=Development. governIntegrationSettings.nodeUrl=https://govern.ds.p.data.slb.com. | X2: The bundle is from a single design node. The URLs suggest the organisation runs a separate deploy/automation estate, but this node uses its own local deployer and has no project-deployer infrastructure attached to push bundles to an automation node. API services (CPS_2, SFP, iSeeds3) are served from this design node's local STATIC infra. Confirm with the customer where production workloads run, and whether the Design -> Deployer -> Automation path is used. | Y2: 2026-09-25 | Z2: Claude (AI-assisted review) - bundle dku_diagnosis_2026-07-22-08-21-05 (node p4d, DSS 14.4.3)
A3: ARCH-002 | B3: nice_to_have | C3: qualitative_practice | D3: Platform Versioning | E3: Regular DSS Version Upgrades | F3: Dataiku recommends customers stay reasonably current on DSS versions to benefit from continuous platform improvements; reviewers should identify and recommend an upgrade if appropriate, but the upgrade itself is a separate service-catalog engagement and should not be performed during the review. | L3: Diagnosis shows a DSS version reasonably close to the latest generally available release. | M3: Diagnosis shows a DSS version many releases behind current, or a version approaching/at end-of-life. | N3: If the diagnosis file lacks version information or there is no context on Dataiku's release cadence, flag needs_manual_review and recommend checking DSS release notes for the customer's version. | O3: Dataiku regularly enriches the platform, so staying current continuously brings value and new opportunities to customers. | P3: DSS version, Upgrade | Q3: architecture_compute_cost | R3: 2 | S3: Dataiku Version | NICE TO HAVE | T3: high | V3: Needs Review | W3: apps/dss/data_design/dss-version.json: product_version=14.4.3 (conf_version 14430). Latest GA found: DSS 15.0.2, released 24 Sep 2026 (15.0.0 released 14 Aug 2026). Source: https://doc.dataiku.com/dss/latest/release_notes/index.html | X3: The bundle is 1 major version behind (14.x vs 15.x). Per the internal rule, a major-version gap means Needs Review, not Fail. Plan a 15.x upgrade as a separate engagement. Remove stale 13.4.2/14.1.4 image references at the same time (see ARCH-010, SCALE-006). | Y3: 2026-09-25 | Z3: Claude (AI-assisted review) - bundle dku_diagnosis_2026-07-22-08-21-05 (node p4d, DSS 14.4.3)
A4: ARCH-003 | B4: must_have | C4: qualitative_practice | D4: Operating System | E4: Supported Operating System Version | F4: DSS should run on an operating system version officially supported by Dataiku, which mainly matters for custom installs since Cloud Stacks provides a supported OS image by default; reviewers should compare the current OS against Dataiku's supported OS list and deprecation notices and recommend upgrades if needed. | L4: Diagnosis or accompanying metadata shows the host OS and version currently listed as supported in Dataiku's Supported Operating Systems documentation. | M4: The host OS/version is deprecated or not on Dataiku's supported list for the installed DSS version. | N4: If the diagnosis file does not capture OS name/version, flag needs_manual_review and cross-check against Dataiku's Supported Operating Systems documentation. | O4: Running on an unsupported OS risks instability and lack of vendor support. | P4: Operating System, Custom install, Cloud Stacks | Q4: architecture_compute_cost | R4: 2 | S4: Operating System Version | MUST HAVE | T4: medium | U4: The source includes an empty 'DiagParser3:' heading with no field specified underneath, so no literal parameter path could be extracted; treated as a qualitative check instead. | V4: Pass | W4: hs_err_pid*.log Host line and diag.txt (/etc/redhat-release): Red Hat Enterprise Linux release 8.10 (Ootpa); kernel 4.18.0-553.144.1.el8_10.x86_64; syspackages.txt: redhat-release-8.10-0.3.el8. | X4: RHEL 8.x is on Dataiku's supported custom-install list for DSS 14 (https://doc.dataiku.com/dss/latest/installation/custom/requirements.html). The page could not be fetched live during this review, so confirm the minor-version floor. Also check that RHEL 8 stays supported for the planned 15.x upgrade (ARCH-002) before scheduling it; RHEL 9 is the longer-lived target. | Y4: 2026-09-25 | Z4: Claude (AI-assisted review) - bundle dku_diagnosis_2026-07-22-08-21-05 (node p4d, DSS 14.4.3)
A5: ARCH-004 | B5: must_have | C5: qualitative_practice | D5: Storage | E5: SSD Storage for DSS | F5: DSS should run on SSD drives rather than legacy rotational hard drives, since rotational disks can significantly degrade performance, especially on larger, multi-user instances (potentially causing a non-workable experience); reviewers should identify currently used disk types and recommend migration to SSD where feasible, noting this is typically easier on cloud than on-premise deployments. | L5: Diagnosis or infrastructure metadata indicates SSD-backed storage underlying the DATADIR. | M5: Diagnosis or infrastructure metadata indicates rotational HDD storage is in use, particularly on a larger or many-user instance. | N5: If the diagnosis file does not report the underlying disk/storage medium, flag needs_manual_review and ask the infrastructure team/customer directly. | O5: Rotational hard drives can severely impact performance and, on larger instances with many users, may lead to a non-workable experience. | P5: Disk I/O, SSD, DATADIR | Q5: architecture_compute_cost | R5: 2, 3 | S5: Use of SSDs | MUST HAVE; Use of SSDs | MUST HAVE | T5: high | V5: Fail | W5: apps/dss/data_design/run/sanity-check.json: WARN_MISC_DISK_ROTATIONAL - DATA_DIR on '/dev/mapper/vg01-vol01' seems to be a rotational hard drive. diag.txt lsblk -t: ROTA=1 for sdb/vg01-vol01 (800G, 74% used, mounted /apps). | X5: DSS's own sanity check flags rotational storage for DATA_DIR. Caveat: this is a GCP VM (hostname gcp9234prdapp04, metadata.google.internal), and GCP persistent disks always report ROTA=1. Confirm the actual PD type (pd-standard is HDD; pd-balanced/pd-ssd are SSD). If it is pd-standard, migrate /apps to pd-balanced or pd-ssd. With 25 users and heavy logs, disk I/O matters. | Y5: 2026-09-25 | Z5: Claude (AI-assisted review) - bundle dku_diagnosis_2026-07-22-08-21-05 (node p4d, DSS 14.4.3)
A6: ARCH-005 | B6: must_have | C6: specific_setting | D6: Spark Configuration | E6: Valid Spark Configuration for Spark Jobs | F6: Environments that run Spark jobs must have a valid Spark configuration set (general-settings.json under sparkSettings, or via Administration > Settings > Spark); the specific example values Dataiku provides are only a baseline, not a strict requirement, but a workable config must exist wherever Spark is used. | G6: general-settings.json > sparkSettings | H6: exists | I6: valid spark configuration present | K6: Required only if the environment executes Spark jobs; the specific parameter values shown by Dataiku are illustrative, not mandatory. | L6: sparkSettings block is present and non-empty in general-settings.json, consistent with evidence of successful Spark job execution elsewhere in the diagnosis. | M6: sparkSettings is missing or empty while the instance shows evidence of Spark recipes/jobs being used. | N6: If the diagnosis file does not indicate whether Spark is used at all, flag needs_manual_review to confirm with the customer whether Spark jobs are run. | O6: Without a valid Spark config, Spark jobs cannot execute at all. | P6: Spark, general-settings.json, sparkSettings | Q6: architecture_compute_cost | R6: 3, 4 | S6: Spark runtime configurations | MUST HAVE if running spark jobs; Spark runtime configurations | MUST HAVE if running spark jobs | T6: high | V6: Pass | W6: apps/dss/data_design/config/general-settings.json sparkSettings.sparkEnabled=true with 3 executionConfigs (spark_small_config/spark_medium_config/spark_large_config), managedKubernetes=true, spark.driver.host=10.196.183.29. backend.log*: 'dku.spark.submit.k8s.helper - Setting up managed Kubernetes context' and 'dku.jobs.postactions.pods - Pods corresponding to job' (Spark on K8s is in use). Spark base images built for 14.4.3 (run/built-base-images.json). | X6: A valid Spark config exists and is being used. Related sanity warning: WARN_CONNECTION_SPARK_NO_GROUP_WITH_DETAILS_READ_ACCESS on 'ear27331_blob_stg_1' (see SCALE-012). The configs are all sized identically (see ARCH-006). | Y6: 2026-09-25 | Z6: Claude (AI-assisted review) - bundle dku_diagnosis_2026-07-22-08-21-05 (node p4d, DSS 14.4.3)
A7: ARCH-006 | B7: nice_to_have | C7: specific_setting | D7: Spark Configuration | E7: Baseline Spark Configuration Set (High/Standard/Large-memory/High I/O) | F7: Dataiku recommends defining multiple named Spark configurations as a tunable baseline: a default Standard config for recipes and notebooks, a High config for higher parallelism, a Large memory config for the largest jobs, and an optional High I/O config for read/write-heavy workloads with a high cores-to-memory ratio. | G7: general-settings.json > sparkSettings (named spark configs) | H7: one_of | I7: Standard/High/Large-memory baseline configs, plus optional High I/O config, as documented | K7: Baseline reference values: Standard config \4, spspark.executor.memory=6g, spark.executor.cores=2, spark.kubernetes.memoryOverheadFactor=0.4, spark.driver.memory=1g, spark.sql.shuffle.partitions=40, spark.sql.broadcastTimeout=3600, spark.port.maxRetries=200, spark.driver.host=<DSS host IP>. High config - spark.executor.instances=12, spark.executor.memory=6g, spark.executor.cores=2, spark.kubernetes.memoryOverheadFactor=0.4, spark.driver.memory=1g, spark.sql.shuffle.partitions=80, spark.sql.broadcastTimeout=3600, spark.port.maxRetries=200, spark.driver.host=<DSS host IP>. Large memory config - spark.executor.instances=4, spark.executor.memory=12g, spark.executor.cores=2, spark.kubernetes.memoryOverheadFactor=0.6, spark.driver.memory=3g, spark.sql.shuffle.partitions=80, spark.sql.broadcastTimeout=3600, spark.port.maxRetries=200, spark.driver.host=<DSS host IP>. Optional High I/O config (only if there is a use case for it) - spark.executor.instances=2, spark.executor.memory=16g, spark.executor.cores=8, spark.kubernetes.memoryOverheadFactor=0.4, spark.driver.memory=3g, spark.sql.shuffle.partitions=40, spark.sql.broadcastTimeout=3600, spark.port.maxRetries=200, spark.driver.host=<DSS host IP>. These values are guidance, not a requirement. | L7: sparkSettings contains multiple named configs roughly matching these purposes (default/high-parallelism/large-memory, and optionally high I/O). | M7: Only a single undifferentiated spark config exists despite varied workload needs (e.g., both lightweight recipes and large jobs run identically). | N7: If the diagnosis file does not list multiple sparkSettings configs or describe workload diversity, flag needs_manual_review and ask about workload variety. | O7: Different Spark workloads (lightweight recipes vs. large jobs vs. I/O-heavy jobs) benefit from different executor sizing and parallelism trade-offs. | P7: Spark executor, Spark configuration, Kubernetes | Q7: architecture_compute_cost | R7: 4, 5 | S7: Define three spark configs - NICE TO HAVE; Special spark configs (only if there's use case for it) | T7: high | V7: Fail | W7: apps/dss/data_design/config/general-settings.json sparkSettings.executionConfigs: spark_small_config, spark_medium_config and spark_large_config all have the same conf: spark.executor.memory=4g, spark.sql.shuffle.partitions=40, spark.kubernetes.memoryOverheadFactor=0.2, spark.kubernetes.executor.limit.cores=1. No spark.executor.instances/cores/driver.memory set. configForJupyter/SEK/Interactive=spark_small_config. | X7: The three named configs suggest intent to tier workloads, but they are functionally identical, so 'medium' and 'large' give no extra capacity. Differentiate them, e.g. medium: executor.instances=12 and shuffle.partitions=80; large: executor.memory=12g, memoryOverheadFactor=0.6, driver.memory=3g. Set explicit executor.instances/cores. Dataiku's baseline values are guidance only. | Y7: 2026-09-25 | Z7: Claude (AI-assisted review) - bundle dku_diagnosis_2026-07-22-08-21-05 (node p4d, DSS 14.4.3)
A8: ARCH-007 | B8: nice_to_have | C8: specific_setting | D8: Spark Configuration | E8: Kubernetes Namespace and Auth Recommendations for Spark | F8: For Spark-on-Kubernetes, Dataiku recommends one Kubernetes namespace per user (e.g. dss-ns-${dssUserLogin}), auto-creating namespaces, ensuring namespace names are Kubernetes-compliant, and dynamically creating service accounts for authentication mode. | G8: general-settings.json > sparkSettings (Kubernetes namespace/authentication settings) | H8: equals | I8: one namespace per user (dss-ns-${dssUserLogin}), auto-create namespaces enabled, K8s-compliant naming, dynamic service account creation | K8: No single literal diag field was given for this sub-setting; pointer is a best-effort conceptual location within sparkSettings/Kubernetes settings. | L8: Namespace naming pattern and auto-create/dynamic service account settings match the recommendation. | M8: A single shared namespace is used for all users, or service accounts are managed manually rather than dynamically. | N8: If the diagnosis file does not expose namespace or authentication configuration for Spark-on-Kubernetes, flag needs_manual_review. | O8: Per-user namespace isolation improves security boundaries and resource tracking on Kubernetes. | P8: Kubernetes namespace, Service account, Spark on Kubernetes | Q8: architecture_compute_cost | R8: 5 | S8: Recommended Settings NICE TO HAVE | T8: medium | V8: Partial | W8: apps/dss/data_design/config/general-settings.json sparkSettings.executionConfigs[*].kubernetesSettings: managedNamespace='${namespace}', authenticationMode=DYNAMIC_SERVICE_ACCOUNT, createNamespace=false, ensureNamespaceCompliance=false. At runtime the namespace resolves per project, not per user: backend.log* shows 'kubectl --namespace dss-29925-p4d' (14,143 occurrences). apps/dss/data_design/config/clusters/P4D.json type=manual. | X8: The per-user namespace shortcut does not apply because this is a manual (externally registered) cluster, so the item was judged on its merits. Dynamic service accounts are used (good). The namespace is templated, but it resolves per project/EAR (dss-<EAR>-p4d) rather than per user. Auto-create and K8s-compliance enforcement are off. This may be a deliberate per-project isolation model; confirm with the customer. If per-user isolation is wanted, use dss-ns-${dssUserLogin}, enable createNamespace and enable ensureNamespaceCompliance. | Y8: 2026-09-25 | Z8: Claude (AI-assisted review) - bundle dku_diagnosis_2026-07-22-08-21-05 (node p4d, DSS 14.4.3)
A9: ARCH-008 | B9: must_have | C9: qualitative_practice | D9: Spark Validation | E9: Functional Validation of Spark Execution (Recipe & Notebook) | F9: Reviewers should functionally validate Spark execution: run a Spark-engine recipe on Kubernetes in a test project (should succeed), and separately launch a Python/R/Scala notebook with starter Spark code and run it locally (should succeed, with Spark executor pods visible in the cluster while the code runs). | L9: Job/notebook execution logs show successful completion of a Spark recipe and a Spark notebook session, and cluster monitoring shows executor pods created during notebook execution. | M9: The Spark recipe or notebook execution fails, hangs, or no executor pods ever appear in the cluster. | N9: If the diagnosis file lacks job/notebook execution logs or cluster pod visibility, flag needs_manual_review and recommend running these test steps manually. | O9: Confirms Spark integration works end-to-end, beyond just having a syntactically valid configuration. | P9: Spark recipe, Spark notebook, Kubernetes executor pods | Q9: architecture_compute_cost | R9: 5, 6, 7 | S9: Additional Spark testing; Spark on Notebook MUST HAVE; Spark on Notebook MUST HAVE | T9: high | V9: Needs Review | W9: backend.log*: 'dku.spark.submit.k8s.helper - Dumping namespace pods state before starting Spark job' (12x) and 'dku.jobs.postactions.pods - Pods corresponding to job' (15x) show Spark jobs launching pods in dss-29925-p4d. No SparkException or failed-job pattern was found. No notebook-side Spark session evidence. | X9: Spark-on-K8s recipes are clearly being submitted, but a static bundle cannot confirm end-to-end success or executor-pod visibility for notebooks. Run the documented test recipe and the Spark notebook test. | Y9: 2026-09-25 | Z9: Claude (AI-assisted review) - bundle dku_diagnosis_2026-07-22-08-21-05 (node p4d, DSS 14.4.3)
A10: ARCH-009 | B10: must_have | C10: qualitative_practice | D10: Network Connectivity | E10: Bidirectional Network Connectivity Between DSS and Elastic AI Cluster | F10: Full bidirectional network connectivity between DSS and the Kubernetes/Elastic AI cluster is mandatory: workers must be able to reach Dataiku (required for Spark to start and for any container execution), and Dataiku must be able to reach workers (required for operations that bring data back to the driver, e.g. toPandas/collect/head/show/broadcast join). This should be validated by running a pySpark recipe that pulls data back to the driver and confirming success via the Main Activity Log. | L10: A pySpark recipe using collect/head/show/toPandas completes successfully, with a corresponding HEAD operation visible in the Main Activity Log, and no worker-to-DSS or DSS-to-worker connectivity errors appear in logs. | M10: Connection timeouts or errors between workers and the DSS host in logs, or driver-return operations failing/hanging. | N10: If the diagnosis file lacks job logs or network topology details, flag needs_manual_review and recommend running the described test recipe. | O10: Both directions of connectivity are mandatory prerequisites for Spark to start and for common data-return operations to work. | P10: Spark driver, Spark workers, Network connectivity, Kubernetes | Q10: architecture_compute_cost | R10: 7 | S10: Connectivity between Dataiku and Elastic AI must be fully open MUST HAVE | T10: high | V10: Needs Review | W10: spark.driver.host=10.196.183.29 is set in every Spark config. backend.log*: 26x java.net.SocketTimeoutException 'Read timed out' and 30x 'Could not stop Kubernetes deployment' [dku.webapps.kubernetes]; several kubectl port-forward 'error forwarding port' / 'connect() failed (Connection refused)' lines. | X10: Worker-to-DSS connectivity works at least for job start (pods are created). The port-forward and read-timeout errors on K8s webapps suggest intermittent DSS <-> cluster connectivity issues. Validate both directions with a pySpark recipe using toPandas()/collect(), and check for a HEAD operation in the Main Activity Log. | Y10: 2026-09-25 | Z10: Claude (AI-assisted review) - bundle dku_diagnosis_2026-07-22-08-21-05 (node p4d, DSS 14.4.3)
A11: ARCH-010 | B11: must_have | C11: specific_setting | D11: Containerized Execution | E11: Valid Containerized Execution Configuration | F11: Environments using Elastic Compute (Kubernetes) must have at least one valid containerized execution configuration set up (general-settings.json > containerSettings, or Administration > Settings > Containerized execution); as with Spark, the specific example values are only a baseline, not a strict requirement. | G11: general-settings.json > containerSettings | H11: exists | I11: valid containerized execution configuration present | K11: Required only when the customer uses Elastic Compute/Kubernetes for offloaded workloads. | L11: containerSettings block is present with at least one named config with reasonable memory requests/limits. | M11: containerSettings is missing or empty while the instance shows evidence of Kubernetes-based execution elsewhere in the diagnosis. | N11: If the diagnosis file does not clarify whether Elastic Compute is used, flag needs_manual_review. | O11: A valid container exec config is required to run workloads in Kubernetes. | P11: Containerized execution, containerSettings, Elastic Compute | Q11: architecture_compute_cost | R11: 8 | S11: Containerized execution configs | MUST HAVE if using Elastic Compute | T11: high | V11: Pass | W11: apps/dss/data_design/config/general-settings.json containerSettings.executionConfigs: 5 KUBERNETES configs. py_small_config 1024/4096MB, py_medium_config 6144/12288MB, py_large_config 8192/16384MB, py_gpu_medium_config 6144/12288MB + 1 GPU, py_gpu_large_config 8192/16384MB + GPU. All have memory/CPU requests and limits. defaultK8sClusterId='P4D'. | X11: A K8s cluster is attached (P4D), so this is a must-have and it is met. Gap: both GPU configs use baseImage 'dataiku-exec-gpu:13.4.2', which the sanity check reports as missing (apps/dss/data_design/run/sanity-check.json WARN_MISC_BASE_IMAGE_NOT_FOUND). GPU workloads will fail until a 14.4.3 GPU image is built and referenced. | Y11: 2026-09-25 | Z11: Claude (AI-assisted review) - bundle dku_diagnosis_2026-07-22-08-21-05 (node p4d, DSS 14.4.3)
A12: ARCH-011 | B12: nice_to_have | C12: specific_setting | D12: Containerized Execution | E12: Baseline Container Execution Configs (Standard, Webapp) and Namespace Settings | F12: Dataiku recommends at least two named containerized execution configs as a baseline - a Standard config for notebooks/recipes/ML (memory request 200MB, memory limit 16000MB) and a Webapp config for webapps (memory request 500MB, memory limit 500MB) - plus per-user Kubernetes namespaces (dss-ns-${dssUserLogin}) with K8s-compliant naming and auto-creation, and using the Webapp config for virtual webapp backends run in containers. | G12: general-settings.json > containerSettings (named container exec configs) | H12: one_of | I12: Standard config (memory request 200MB / limit 16000MB) and Webapp config (memory request 500MB / limit 500MB) | J12: MB | K12: Additional recommended settings: one Kubernetes namespace per user (dss-ns-${dssUserLogin}), K8s-compliant namespace names, auto-create namespaces, and virtual webapps configured to run in a container using the Webapp config. | L12: containerSettings includes configs resembling the Standard and Webapp purposes with comparable memory request/limit values, and namespace settings follow a per-user pattern. | M12: A single undifferentiated container config is used for both interactive workloads and webapps, or all users share one namespace. | N12: If the diagnosis file does not list named container configs or namespace settings, flag needs_manual_review. | O12: Separating configs by workload type avoids over- or under-provisioning; per-user namespaces aid isolation and cost tracking. | P12: Containerized execution, Kubernetes namespace, Webapp backend | Q12: architecture_compute_cost | R12: 8, 9 | S12: Recommendations NICE TO HAVE; Recommended Settings | T12: high | V12: Pass | W12: apps/dss/data_design/config/general-settings.json containerSettings: several configs with genuinely different sizes (requests/limits 1G/4G, 6G/12G, 8G/16G, plus GPU variants). virtualWebAppBackendSettings.infra.containerSelection = EXPLICIT_CONTAINER py_small_config. kubernetesNamespace='${namespace}' on all configs (resolves to dss-29925-p4d at runtime). | X12: Pass under the internal calibration: more than one container config with varying sizes is sufficient, even though names and figures differ from the Standard/Webapp example. Notes: (1) virtual webapps run in py_small_config (1G/4G); a dedicated small webapp config would be cleaner. (2) Namespaces resolve per project, not per user (see ARCH-007), and createNamespace/ensureNamespaceCompliance are false. | Y12: 2026-09-25 | Z12: Claude (AI-assisted review) - bundle dku_diagnosis_2026-07-22-08-21-05 (node p4d, DSS 14.4.3)
A13: ARCH-012 | B13: must_have | C13: qualitative_practice | D13: Containerized Execution Validation | E13: Functional Validation of Containerized Execution Across Recipe, Notebook, Webapp, and API | F13: Reviewers should validate containerized execution end-to-end: execute a recipe in Kubernetes, launch a notebook in the cluster (pod visible in Cluster Monitoring UI), create a test webapp configured with a container backend (deployment visible in Cluster Monitoring UI), and deploy an API service to Kubernetes via the API Deployer (deployment visible in Cluster Monitoring UI and callable via sample code). | L13: Cluster monitoring evidence or reviewer test logs show successful recipe execution, a notebook pod, a webapp deployment, and an API deployment all running in Kubernetes, with the API additionally callable via sample code. | M13: Any of the four (recipe, notebook, webapp, API) fails to launch, or no corresponding pods/deployments ever appear in Cluster Monitoring. | N13: If the diagnosis file does not include cluster monitoring or job execution evidence for these workload types, flag needs_manual_review and recommend running these four test steps manually. | O13: Confirms containerized execution actually works for all major workload types, not merely that configuration exists. | P13: Kubernetes, Recipe, Notebook, Webapp, API Deployer, Cluster Monitoring | Q13: architecture_compute_cost | R13: 9, 10, 11, 12 | S13: Additional container execution testing; Webapp MUST HAVE; API MUST HAVE; API MUST HAVE | T13: high | V13: Needs Review | W13: backend.log*: many streamlit/code-studio K8s deployments (e.g. 'kubectl --namespace dss-29925-p4d get deployments -l dataiku.com/dku-execution-id=streamlit-...'), 7,857 'Getting webapp log tail'. 6,840x ERROR '/dip/api/tintercom/containers/get-execution' failed: 'Unknown execution context: code-studio-as-webapp-...'. api-deployer infra P4D_Local type=STATIC (not K8s). | X13: Webapps and code studios run on K8s, but the recurring intercom 'Unknown execution context' errors point to orphaned or stale container executions calling back. API services are deployed to a STATIC infra, not K8s, so the API-on-K8s test has no evidence. Run the four functional tests (recipe, notebook, webapp, API). | Y13: 2026-09-25 | Z13: Claude (AI-assisted review) - bundle dku_diagnosis_2026-07-22-08-21-05 (node p4d, DSS 14.4.3)
A14: ARCH-013 | B14: must_have | C14: specific_setting | D14: Cluster Configuration | E14: Valid Cluster Configuration for Elastic Compute | F14: Environments using Elastic Compute must have at least one valid cluster configured (found under {DATADIR}/config/clusters or Administration > Clusters); Dataiku does not mandate the specific example configuration, only that a workable cluster exists. | G14: {DATADIR}/config/clusters | H14: exists | I14: at least one valid cluster configuration present | L14: The clusters config/directory contains at least one properly defined cluster, consistent with other evidence of elastic-compute usage (spark/container jobs running on Kubernetes). | M14: No cluster configuration is present despite evidence of Kubernetes-based workloads elsewhere in the diagnosis. | N14: If the diagnosis file does not clarify whether Elastic Compute is used at all, flag needs_manual_review. | O14: A valid cluster is required to offload computation to Kubernetes. | P14: Cluster, Managed cluster, Unmanaged cluster, Elastic AI | Q14: architecture_compute_cost | R14: 12, 13 | S14: Cluster configurations | MUST HAVE if using Elastic Compute; Cluster configurations | MUST HAVE if using Elastic Compute | T14: high | V14: Pass | W14: apps/dss/data_design/config/clusters/P4D.json: name=P4D, architecture=KUBERNETES, type=manual, permissions granted to 9 groups. apps/dss/data_design/config/general-settings.json defaultK8sClusterId='P4D'. | X14: A valid K8s cluster definition exists and is the global default. It is a manual (externally managed) cluster; see ARCH-014 for topology. | Y14: 2026-09-25 | Z14: Claude (AI-assisted review) - bundle dku_diagnosis_2026-07-22-08-21-05 (node p4d, DSS 14.4.3)
A15: ARCH-014 | B15: nice_to_have | C15: specific_setting | D15: Cluster Configuration | E15: Recommended Cluster Topology (Single Managed Cluster, Node Groups, Autoscaling) | F15: Dataiku recommends a single managed cluster with one CPU node group serving containerized execution, ML, Spark, webapp, and API workloads, adding a separate GPU node group only if needed, and enabling a metrics server plus cluster autoscaling. | G15: {DATADIR}/config/clusters (cluster topology / node group / autoscaling settings) | H15: equals | I15: single managed cluster, one CPU node group for all standard workloads, optional GPU node group only if needed, metrics server installed, autoscaling enabled | K15: No literal single field was given for this recommendation; pointer is a best-effort conceptual location within the clusters config. | L15: Cluster configuration shows one managed cluster with a shared CPU node group, autoscaling enabled, metrics server installed, and a GPU node group only present when GPU workloads exist. | M15: Multiple redundant clusters/node groups without clear justification, no autoscaling enabled, or a GPU node group present without any GPU workload evidence. | N15: If the diagnosis file does not detail node groups or autoscaling settings, flag needs_manual_review. | O15: Simplifies management and reduces cost while retaining elasticity for varying workloads. | P15: Managed cluster, Node group, Autoscaling, Metrics server | Q15: architecture_compute_cost | R15: 14 | S15: Recommended settings NICE TO HAVE | T15: medium | V15: Partial | W15: apps/dss/data_design/config/clusters/P4D.json: single cluster, type=manual, params={} (no node-group, autoscaling or metrics-server details are visible to DSS). | X15: One cluster is used (aligned). It is manually registered, not a DSS-managed cluster, so node groups, autoscaling and metrics server cannot be verified from the bundle. GPU configs exist while the GPU image is missing. Confirm the GKE node pools (CPU plus an optional GPU pool), cluster autoscaler and metrics-server with the infra team. | Y15: 2026-09-25 | Z15: Claude (AI-assisted review) - bundle dku_diagnosis_2026-07-22-08-21-05 (node p4d, DSS 14.4.3)
A16: ARCH-015 | B16: must_have | C16: specific_setting | D16: Cluster Sizing | E16: Appropriate Cluster Sizing | F16: The Kubernetes cluster must be sized appropriately for the customer's workloads - large enough to avoid resource exhaustion but not so large as to waste resources. Dataiku's memory/disk calculation is only an illustrative baseline (not a mandatory formula), derived from Spark settings (general-settings.json > sparkSettings), container exec settings (general-settings.json > containerSettings), and global flow concurrency (general-settings.json > maxRunningActivities). | G16: general-settings.json > sparkSettings, general-settings.json > containerSettings, general-settings.json > maxRunningActivities (used to estimate cluster memory/disk sizing) | H16: greater_than_or_equal | I16: cluster capacity >= estimated total_memory and disk needs derived from the formulas in notes | J16: GB | K16: Illustrative sizing formulas provided by Dataiku, reproduced in full: spark_recipes_memory = global flow concurrency*spark.executor.instances*spark.executor.memory*(1+spark.kubernetes.memoryOverheadFactor) [based on the largest spark config]. spark_notebooks_memory = 30%_DSS_users*spark.executor.instances*spark.executor.memory*(1+spark.kubernetes.memoryOverheadFactor) [using associated spark config]. jupyter_notebooks_memory = 30%_DSS_users * container exec memory limit [using associated container exec config]. total_memory = spark_recipes_memory + spark_notebooks_memory + jupyter_notebooks_memory. DISK = 25GB * spark.executor.instances. Recommended instance sizing: 64 GB < worker size < 128 GB. These are baselines/examples; the cluster need not match this exact calculation, but must be appropriately sized for the customer's workloads based on evidence, and should not be resized without evidence of resource exhaustion. | L16: Cluster memory/CPU capacity is consistent with or exceeds the estimated total_memory/disk needs given current spark/container/concurrency settings, with no signs of chronic resource exhaustion (OOM kills, pending pods) or gross over-provisioning. | M16: Cluster capacity is far below estimated needs (frequent OOM kills/evictions) or drastically oversized relative to workload with no growth justification. | N16: If the diagnosis file lacks cluster capacity metrics or the underlying spark/container/concurrency settings needed to compute the estimate, flag needs_manual_review and recommend gathering these values. | O16: Prevents both instability/performance degradation from under-sizing and cost waste from over-sizing. | P16: Cluster sizing, Spark executor memory, Container exec memory limit, maxRunningActivities, Global flow concurrency | Q16: architecture_compute_cost | R16: 14, 15 | S16: Cluster sizing | MUST HAVE; Cluster sizing | MUST HAVE | T16: high | V16: Needs Review | W16: No cluster capacity metrics in the bundle. Inputs: apps/dss/data_design/config/general-settings.json maxRunningActivities=5; Spark configs 4g executor, overhead 0.2, executor.instances unset (default 2); container limits up to 16384MB; 25 enabled users (config/users.json). | X16: Illustrative estimate from Dataiku's formula: Spark recipes about 5 x 2 x 4g x 1.2 = 48GB; Spark notebooks about 8 (30% of 25 users) x 2 x 4g x 1.2 = 77GB; Jupyter about 8 x 4GB (py_small limit) = 32GB. Total about 157GB of cluster memory, plus disk about 25GB x executor instances. Get the GKE node-pool size and utilisation, and any pending-pod or OOMKilled history, before judging sizing. | Y16: 2026-09-25 | Z16: Claude (AI-assisted review) - bundle dku_diagnosis_2026-07-22-08-21-05 (node p4d, DSS 14.4.3)
A17: ARCH-016 | B17: must_have | C17: specific_setting | D17: Default Compute Settings | E17: Global Default Cluster and Default Execution Config Set (if Elastic AI used) | F17: If the customer intends to offload most or all recipes to Kubernetes, a default cluster (general-settings.json > defaultK8sClusterId) and a default containerized execution config (general-settings.json > defaultExecutionConfig) should be set globally rather than configured per-recipe or per-project; if this global default is set, the associated execution config must have properly configured resource requests/limits rather than being a resource-hogging default. | G17: general-settings.json > defaultK8sClusterId and general-settings.json > defaultExecutionConfig | H17: exists | I17: both set to valid, non-resource-hogging values when Elastic AI/offloading is used broadly | L17: Both defaultK8sClusterId and defaultExecutionConfig are set to valid values, and the referenced execution config has reasonable memory/CPU requests and limits. | M17: These fields are unset despite most recipes being offloaded to Kubernetes, or the default execution config lacks resource limits/requests (resource-hogging risk). | N17: If the diagnosis file does not clarify the proportion of recipes offloaded to Kubernetes, flag needs_manual_review to confirm intended usage pattern with the customer. | O17: Setting a global default simplifies configuration management and avoids inconsistent per-recipe settings; an unset or misconfigured default risks uncontrolled resource usage. | P17: defaultK8sClusterId, defaultExecutionConfig, Containerized execution, Elastic AI | Q17: architecture_compute_cost | R17: 15, 16 | S17: Default Cluster & Default Containerized Execution Config | MUST HAVE if Elastic AI is used; Default Cluster & Default Containerized Execution Config | MUST HAVE if Elastic AI is used | T17: high | V17: Partial | W17: apps/dss/data_design/config/general-settings.json defaultK8sClusterId='P4D' (set); containerSettings.defaultExecutionConfig='' (empty). | X17: The default cluster is set, but no global default container config is set, so recipes and notebooks run locally unless each one is configured. If most workloads are meant to be offloaded (which the heavy K8s webapp/Spark use suggests), set defaultExecutionConfig to a bounded config such as py_small_config or py_medium_config. This also relieves memory pressure on the 62GB host (see SCALE-009). | Y17: 2026-09-25 | Z17: Claude (AI-assisted review) - bundle dku_diagnosis_2026-07-22-08-21-05 (node p4d, DSS 14.4.3)
A18: ARCH-017 | B18: nice_to_have | C18: specific_setting | D18: Containerized Visual Recipes | E18: Containerized Visual Recipes (CDE) Enabled and Base Image Built | F18: If the customer intends to offload visual recipes to Kubernetes, CDE should be enabled (general-settings.json > cdeEnabled) and its base image built via Administration > Settings > Containerized Execution > Build image for containerized visual recipes; a default execution config for visual recipe workloads (general-settings.json > defaultExecutionConfigForVisualRecipesWorkloads) should also be set, validated by confirming a simple recipe (e.g. a sync recipe) shows Engine: DSS (containerized). | G18: general-settings.json > cdeEnabled and general-settings.json > defaultExecutionConfigForVisualRecipesWorkloads | H18: equals | I18: cdeEnabled=true and defaultExecutionConfigForVisualRecipesWorkloads set to a valid execution config | L18: cdeEnabled is true, base CDE image build evidence exists, defaultExecutionConfigForVisualRecipesWorkloads is set, and a sample visual recipe shows Engine: DSS (containerized). | M18: cdeEnabled is false or unset while the customer relies on Kubernetes offloading for visual recipes, or a visual recipe fails to show the containerized engine. | N18: If the diagnosis file does not indicate whether visual recipe offloading to Kubernetes is desired, flag needs_manual_review. | O18: Ensures visual recipes can actually be executed on the cluster with an appropriate base image and default resource config. | P18: CDE, cdeEnabled, Visual recipes, Containerized execution | Q18: architecture_compute_cost | R18: 16, 17, 18 | S18: Containerized Visual Recipes (CDE) | NICE TO HAVE; Containerized Visual Recipes (CDE) | NICE TO HAVE; Containerized Visual Recipes (CDE) | NICE TO HAVE | T18: high | V18: Partial | W18: apps/dss/data_design/config/general-settings.json containerSettings.cdeEnabled=true, cdePluginSupport=true; defaultExecutionConfigForVisualRecipesWorkloads='' (empty). apps/dss/data_design/run/cde-images.json = {} (no CDE image recorded). | X18: CDE is switched on, but no visual-recipe default config is set and no CDE image build is recorded, so visual recipes cannot actually run containerised. Build the CDE image (Admin > Settings > Containerized Execution), set defaultExecutionConfigForVisualRecipesWorkloads, and check that a Sync recipe shows 'Engine: DSS (containerized)'. If visual-recipe offload is not wanted, switch cdeEnabled off to avoid confusion. | Y18: 2026-09-25 | Z18: Claude (AI-assisted review) - bundle dku_diagnosis_2026-07-22-08-21-05 (node p4d, DSS 14.4.3)

Sheet Enterprise-grade Security, Perm
A1: id | B1: priority | C1: check_type | D1: subtopic | E1: title | F1: statement | G1: parameter_hint | H1: operator | I1: expected_value | J1: unit | K1: expected_condition_notes | L1: supporting_evidence | M1: contradicting_evidence | N1: insufficient_evidence_handling | O1: rationale | P1: dataiku_concepts | Q1: source_document | R1: source_page | S1: source_section | T1: confidence | U1: ambiguity_notes | V1: validation_status | W1: evidence_found | X1: notes | Y1: validated_at | Z1: validated_by
A2: SEC-001 | B2: nice_to_have | C2: qualitative_practice | D2: Instance Identification | E2: Verify/Capture Instance IDs | F2: For an established platform, confirm that each node's instance ID (found in {DATA_DIR}/install.ini) is accurately recorded in the platform's tracking/tooling system. | L2: Platform tooling/documentation shows an instance ID for each node matching the value found in {DATA_DIR}/install.ini on that node. | M2: Instance IDs are missing, blank, or mismatched between install.ini and the platform tooling records. | N2: A diagnosis file alone can show the instance ID value in install.ini but cannot confirm whether it is accurately recorded in external platform tooling; flag as needs_manual_review to cross-check against the tooling record. | O2: Accurate instance ID records ensure the platform tooling correctly tracks and manages each node. | P2: install.ini, instance tracking | Q2: security_permissions_compliance | R2: 1, 2 | S2: Verify/Capture Instance IDs | NICE TO HAVE; DiagParser3 | T2: medium | U2: No literal JSON field/diag pointer given beyond the file path itself; this is more a documentation-accuracy check than a technical setting. | V2: Needs Review | W2: apps/dss/data_design/install.ini [general]: installid=GbpIpatzv3MFrFfE6MwSlXCg, nodeid=p4d, nodetype=design. | X2: The instance ID is present and was captured above. Cross-check it against the platform tooling / CMDB record for this node. | Y2: 2026-09-25 | Z2: Claude (AI-assisted review) - bundle dku_diagnosis_2026-07-22-08-21-05 (node p4d, DSS 14.4.3)
